Loading synthetic dataset from: fire_tv_synthetic_dataset_v3_tmdb.csv
Traceback (most recent call last):
  File "c:\Users\solos\OneDrive\Documents\College\Projects\Advanced Behavioural Analysis for Content Recommendation\Shosyn\fire_tv_neural_cde_transformer_instance_version\Shosyn-1.0\fire_tv_project\fire_tv_neural_cde_transformer\data\synthetic_data_loader.py", line 14, in __init__
    self.df = pd.read_csv(csv_path)
              ~~~~~~~~~~~^^^^^^^^^^
  File "C:\Users\solos\OneDrive\Documents\College\Projects\Advanced Behavioural Analysis for Content Recommendation\Shosyn\venv\Lib\site-packages\pandas\io\parsers\readers.py", line 1026, in read_csv
    return _read(filepath_or_buffer, kwds)
  File "C:\Users\solos\OneDrive\Documents\College\Projects\Advanced Behavioural Analysis for Content Recommendation\Shosyn\venv\Lib\site-packages\pandas\io\parsers\readers.py", line 620, in _read
    parser = TextFileReader(filepath_or_buffer, **kwds)
  File "C:\Users\solos\OneDrive\Documents\College\Projects\Advanced Behavioural Analysis for Content Recommendation\Shosyn\venv\Lib\site-packages\pandas\io\parsers\readers.py", line 1620, in __init__
    self._engine = self._make_engine(f, self.engine)
                   ~~~~~~~~~~~~~~~~~^^^^^^^^^^^^^^^^
  File "C:\Users\solos\OneDrive\Documents\College\Projects\Advanced Behavioural Analysis for Content Recommendation\Shosyn\venv\Lib\site-packages\pandas\io\parsers\readers.py", line 1880, in _make_engine
    self.handles = get_handle(
                   ~~~~~~~~~~^
        f,
        ^^
    ...<6 lines>...
        storage_options=self.options.get("storage_options", None),
        ^^^^^^^^^^^^^^^^^^^^^^^^^^^^^^^^^^^^^^^^^^^^^^^^^^^^^^^^^^
    )
    ^
  File "C:\Users\solos\OneDrive\Documents\College\Projects\Advanced Behavioural Analysis for Content Recommendation\Shosyn\venv\Lib\site-packages\pandas\io\common.py", line 873, in get_handle
    handle = open(
        handle,
    ...<3 lines>...
        newline="",
    )
FileNotFoundError: [Errno 2] No such file or directory: 'fire_tv_synthetic_dataset_v3_tmdb.csv'

During handling of the above exception, another exception occurred:

Traceback (most recent call last):
  File "c:\Users\solos\OneDrive\Documents\College\Projects\Advanced Behavioural Analysis for Content Recommendation\Shosyn\fire_tv_neural_cde_transformer_instance_version\Shosyn-1.0\fire_tv_project\fire_tv_neural_cde_transformer\scripts\train_hybrid_model_tmdb.py", line 129, in <module>
    main()
    ~~~~^^
  File "c:\Users\solos\OneDrive\Documents\College\Projects\Advanced Behavioural Analysis for Content Recommendation\Shosyn\fire_tv_neural_cde_transformer_instance_version\Shosyn-1.0\fire_tv_project\fire_tv_neural_cde_transformer\scripts\train_hybrid_model_tmdb.py", line 34, in main
    full_dataset = SyntheticFireTVDataset("fire_tv_synthetic_dataset_v3_tmdb.csv")
  File "c:\Users\solos\OneDrive\Documents\College\Projects\Advanced Behavioural Analysis for Content Recommendation\Shosyn\fire_tv_neural_cde_transformer_instance_version\Shosyn-1.0\fire_tv_project\fire_tv_neural_cde_transformer\data\synthetic_data_loader.py", line 16, in __init__
    raise FileNotFoundError(f"CRITICAL ERROR: The dataset file was not found at '{csv_path}'. Please check the path.")
FileNotFoundError: CRITICAL ERROR: The dataset file was not found at 'fire_tv_synthetic_dataset_v3_tmdb.csv'. Please check the path.
